<?xml version="1.0"?>
<robot xmlns:xacro="http://ros.org/wiki/xacro">
         
	  <xacro:macro name="legA" params="prefix parent *joint_origin *joint_axis ">
	    <joint name="leg${prefix}_A_joint" type="revolute">
	      <xacro:insert_block name="joint_origin" />
	      <xacro:insert_block name="joint_axis" />
	      <limit effort="100" lower="-1.0" upper="1.0" velocity="10"/>
	      <parent link="${parent}" />
	      <child link="leg${prefix}_A_link" />
	    </joint>
	    
	    <transmission name="legA_trans">
	      <type>transmission_interface/SimpleTransmission</type>
	      <joint name="leg${prefix}_A_joint">
	        <hardwareInterface>hardware_interface/PositionJointInterface</hardwareInterface>
	      </joint>
	      <actuator name="leg1_motor">
	        <hardwareInterface>hardware_interface/PositionointInterface</hardwareInterface>
	        <mechanismReduction>1</mechanismReduction>
	      </actuator>
	    </transmission>
	    
	    <link name="leg${prefix}_A_link">
	      <visual>
	        <geometry>
	          <mesh filename="file://$(find multi_legged_robo_description)/meshes/first_link.stl"/>
	        </geometry>
	      </visual>
	      
	      <collision>
	        <geometry>
	          <mesh filename="file://$(find multi_legged_robo_description)/meshes/first_link.dae"/>
	        </geometry>
	      </collision>
	      
	      <inertial>
	        <origin xyz="0 -0.02 0" />
	        <mass value="0.121"/>
	        <inertia ixx="0.00001" ixy="0.0" ixz="0.0" iyy="0.00001" iyz="0.0" izz="0.00001" />
	      </inertial>
	    </link>
		<gazebo reference="leg${prefix}_A_link">
			<material>Gazebo/Red</material>
			<turnGravityOff>false</turnGravityOff>
		</gazebo>
		
		
		
	  </xacro:macro>
	  
  
	  
</robot>

